<?xml version="1.0" ?>
<!-- =================================================================================== -->
<!-- |    This document was autogenerated by xacro from src/fishbot_description/urdf/fishbot/fishbot.urdf.xacro | -->
<!-- |    EDITING THIS FILE BY HAND IS NOT RECOMMENDED                                 | -->
<!-- =================================================================================== -->
<robot name="fishbot">
  <gazebo>
    <plugin filename="libgazebo_ros_diff_drive.so" name="diff_drive">
      <ros>
        <namespace>/</namespace>
        <remapping>cmd_vel:=cmd_vel</remapping>
        <remapping>odom:=odom</remapping>
      </ros>
      <update_rate>30</update_rate>
      <!-- wheels -->
      <left_joint>left_wheel_joint</left_joint>
      <right_joint>right_wheel_joint</right_joint>
      <!-- kinematics -->
      <wheel_separation>0.2</wheel_separation>
      <wheel_diameter>0.064</wheel_diameter>
      <!-- limits -->
      <max_wheel_torque>20.0</max_wheel_torque>
      <max_wheel_acceleration>1.0</max_wheel_acceleration>
      <!-- output -->
      <publish_odom>true</publish_odom>
      <publish_odom_tf>true</publish_odom_tf>
      <publish_wheel_tf>true</publish_wheel_tf>
      <odometry_frame>odom</odometry_frame>
      <robot_base_frame>base_footprint</robot_base_frame>
    </plugin>
  </gazebo>
  <gazebo reference="laser_link">
    <sensor name="laserscan" type="ray">
      <plugin filename="libgazebo_ros_ray_sensor.so" name="laserscan">
        <ros>
          <namespace>/</namespace>
          <remapping>~/out:=scan</remapping>
        </ros>
        <output_type>sensor_msgs/LaserScan</output_type>
        <frame_name>laser_link</frame_name>
      </plugin>
      <always_on>true</always_on>
      <visualize>true</visualize>
      <update_rate>5</update_rate>
      <pose>0 0 0 0 0 0</pose>
      <!-- 激光传感器配置 -->
      <ray>
        <!-- 设置扫描范围 -->
        <scan>
          <horizontal>
            <samples>360</samples>
            <resolution>1</resolution>
            <min_angle>0.000000</min_angle>
            <max_angle>6.280000</max_angle>
          </horizontal>
        </scan>
        <!-- 设置扫描距离 -->
        <range>
          <min>0.120000</min>
          <max>8.0</max>
          <resolution>0.015000</resolution>
        </range>
        <!-- 设置噪声-->
        <noise>
          <type>gaussian</type>
          <mean>0.0</mean>
          <stddev>0.01</stddev>
        </noise>
      </ray>
    </sensor>
  </gazebo>
  <gazebo reference="imu_sensor">
    <sensor name="imu_sensor" type="imu">
      <plugin filename="libgazebo_ros_imu_sensor.so" name="imu_plugin">
        <ros>
          <namespace>/</namespace>
          <remapping>~/out:=imu</remapping>
        </ros>
        <initial_orientation_as_reference>false</initial_orientation_as_reference>
      </plugin>
      <update_rate>100</update_rate>
      <always_on>true</always_on>
      <!-- 六轴噪声设置 -->
      <imu>
        <angular_velocity>
          <x>
            <noise type="gaussian">
              <mean>0.0</mean>
              <stddev>2e-4</stddev>
              <bias_mean>0.0000075</bias_mean>
              <bias_stddev>0.0000008</bias_stddev>
            </noise>
          </x>
          <y>
            <noise type="gaussian">
              <mean>0.0</mean>
              <stddev>2e-4</stddev>
              <bias_mean>0.0000075</bias_mean>
              <bias_stddev>0.0000008</bias_stddev>
            </noise>
          </y>
          <z>
            <noise type="gaussian">
              <mean>0.0</mean>
              <stddev>2e-4</stddev>
              <bias_mean>0.0000075</bias_mean>
              <bias_stddev>0.0000008</bias_stddev>
            </noise>
          </z>
        </angular_velocity>
        <linear_acceleration>
          <x>
            <noise type="gaussian">
              <mean>0.0</mean>
              <stddev>1.7e-2</stddev>
              <bias_mean>0.1</bias_mean>
              <bias_stddev>0.001</bias_stddev>
            </noise>
          </x>
          <y>
            <noise type="gaussian">
              <mean>0.0</mean>
              <stddev>1.7e-2</stddev>
              <bias_mean>0.1</bias_mean>
              <bias_stddev>0.001</bias_stddev>
            </noise>
          </y>
          <z>
            <noise type="gaussian">
              <mean>0.0</mean>
              <stddev>1.7e-2</stddev>
              <bias_mean>0.1</bias_mean>
              <bias_stddev>0.001</bias_stddev>
            </noise>
          </z>
        </linear_acceleration>
      </imu>
    </sensor>
  </gazebo>
  <!-- 底盘 -->
  <link name="base_footprint"/>
  <joint name="base_joint" type="fixed">
    <parent link="base_footprint"/>
    <child link="base_link"/>
    <origin rpy="0 0 0" xyz="0 0 0.091"/>
  </joint>
  <link name="base_link">
    <!-- 部件外观描述 -->
    <visual>
      <!-- 沿自己几何中心的偏移与旋转 -->
      <origin rpy="0 0 0" xyz="0 0 0"/>
      <!-- 几何形状 -->
      <geometry>
        <!-- 圆柱体， 半径为0.10m，高度为0.12m -->
        <cylinder length="0.12" radius="0.1"/>
      </geometry>
      <!-- 材料属性 -->
      <material name="white">
        <color rgba="1.0 1.0 1.0 0.5"/>
      </material>
    </visual>
    <!-- 碰撞属性 -->
    <collision>
      <origin rpy="0 0 0" xyz="0 0 0"/>
      <geometry>
        <cylinder length="0.12" radius="0.1"/>
      </geometry>
      <material name="white">
        <color rgba="1.0 1.0 1.0 0.5"/>
      </material>
    </collision>
    <inertial>
      <mass value="1.0"/>
      <inertia ixx="0.0037000000000000006" ixy="0.0" ixz="0.0" iyy="0.0037000000000000006" iyz="0.0" izz="0.005000000000000001"/>
    </inertial>
  </link>
  <gazebo reference="imu_link">
    <material>Gazebo/Black</material>
  </gazebo>
  <link name="imu_link">
    <visual>
      <origin rpy="0 0 0" xyz="0 0 0"/>
      <geometry>
        <box size="0.02 0.02 0.02"/>
      </geometry>
      <material name="black">
        <color rgba="0 0 0 0.8"/>
      </material>
    </visual>
    <!-- 碰撞检测 -->
    <collision>
      <origin rpy="0 0 0" xyz="0 0 0"/>
      <geometry>
        <box size="0.02 0.02 0.02"/>
      </geometry>
      <material name="black">
        <color rgba="0 0 0 0.8"/>
      </material>
    </collision>
    <inertial>
      <mass value="1.0"/>
      <inertia ixx="6.666666666666667e-05" ixy="0.0" ixz="0.0" iyy="6.666666666666667e-05" iyz="0.0" izz="6.666666666666667e-05"/>
    </inertial>
  </link>
  <!-- 机器人IMU与身体的连接 -->
  <joint name="imu_joint" type="fixed">
    <parent link="base_link"/>
    <child link="imu_link"/>
    <!-- 子部件相对父部件的偏移与旋转 -->
    <origin xyz="0 0 0.02"/>
  </joint>
  <gazebo reference="laser_cylinder_link">
    <material>Gazebo/Black</material>
  </gazebo>
  <gazebo reference="laser_link">
    <material>Gazebo/Black</material>
  </gazebo>
  <!-- 雷达支撑杆 -->
  <link name="laser_cylinder_link">
    <visual>
      <origin rpy="0 0 0" xyz="0 0 0"/>
      <geometry>
        <cylinder length="0.10" radius="0.01"/>
      </geometry>
      <material name="green">
        <color rgba="0.0 1.0 0.0 0.8"/>
      </material>
    </visual>
    <!-- 碰撞检测 -->
    <collision>
      <origin rpy="0 0 0" xyz="0 0 0"/>
      <geometry>
        <cylinder length="0.10" radius="0.01"/>
      </geometry>
      <material name="green">
        <color rgba="0.0 1.0 0.0 0.8"/>
      </material>
    </collision>
    <inertial>
      <mass value="1.0"/>
      <inertia ixx="0.0008583333333333335" ixy="0.0" ixz="0.0" iyy="0.0008583333333333335" iyz="0.0" izz="5e-05"/>
    </inertial>
  </link>
  <joint name="laser_cylinder_joint" type="fixed">
    <parent link="base_link"/>
    <child link="laser_cylinder_link"/>
    <origin xyz="0 0 0.1"/>
  </joint>
  <!-- 雷达 -->
  <link name="laser_link">
    <visual>
      <origin rpy="0 0 0" xyz="0 0 0"/>
      <geometry>
        <cylinder length="0.02" radius="0.02"/>
      </geometry>
      <material name="red">
        <color rgba="1.0 0.0 0.0 0.8"/>
      </material>
    </visual>
    <!-- 碰撞检测 -->
    <collision>
      <origin rpy="0 0 0" xyz="0 0 0"/>
      <geometry>
        <cylinder length="0.02" radius="0.02"/>
      </geometry>
      <material name="red">
        <color rgba="1.0 0.0 0.0 0.8"/>
      </material>
    </collision>
  </link>
  <joint name="laser_joint" type="fixed">
    <parent link="laser_cylinder_link"/>
    <child link="laser_link"/>
    <origin xyz="0 0 0.05"/>
  </joint>
  <gazebo reference="camera_link">
    <material>Gazebo/Green</material>
  </gazebo>
  <link name="camera_link">
    <visual>
      <origin rpy="0 0 0" xyz="0 0 0.0"/>
      <geometry>
        <box size="0.02 0.10 0.02"/>
      </geometry>
      <material name="green">
        <color rgba="0.0 1.0 0.0 0.8"/>
      </material>
    </visual>
    <!-- 碰撞检测 -->
    <collision>
      <origin rpy="0 0 0" xyz="0 0 0.0"/>
      <geometry>
        <box size="0.02 0.10 0.02"/>
      </geometry>
      <material name="green">
        <color rgba="0.0 1.0 0.0 0.8"/>
      </material>
    </collision>
    <inertial>
      <mass value="1.0"/>
      <inertia ixx="6.666666666666667e-05" ixy="0.0" ixz="0.0" iyy="0.0008666666666666667" iyz="0.0" izz="0.0008666666666666667"/>
    </inertial>
  </link>
  <!-- 机器人相机与身体的连接 -->
  <joint name="camera_joint" type="fixed">
    <parent link="base_link"/>
    <child link="camera_link"/>
    <!-- 子部件相对父部件的偏移与旋转 -->
    <origin xyz="0.1 0 0.075"/>
  </joint>
  <gazebo reference="left_wheel_link">
    <material>Gazebo/Blue</material>
  </gazebo>
  <link name="left_wheel_link">
    <visual>
      <origin rpy="1.57079 0 0" xyz="0 0 0"/>
      <geometry>
        <cylinder length="0.04" radius="0.032"/>
      </geometry>
      <material name="yellow">
        <color rgba="1.0 1.0 0.0 0.8"/>
      </material>
    </visual>
    <!-- 碰撞检测 -->
    <collision>
      <origin rpy="1.57079 0 0" xyz="0 0 0"/>
      <geometry>
        <cylinder length="0.04" radius="0.032"/>
      </geometry>
      <material name="yellow">
        <color rgba="1.0 1.0 0.0 0.8"/>
      </material>
    </collision>
    <inertial>
      <mass value="1.0"/>
      <inertia ixx="0.00038933333333333333" ixy="0.0" ixz="0.0" iyy="0.00038933333333333333" iyz="0.0" izz="0.000512"/>
    </inertial>
  </link>
  <joint name="left_wheel_joint" type="continuous">
    <parent link="base_link"/>
    <child link="left_wheel_link"/>
    <origin xyz="0 0.1 -0.06"/>
    <axis xyz="0 1 0"/>
  </joint>
  <!-- 修改摩擦力系数 -->
  <gazebo reference="left_wheel_link">
    <!-- 切向摩擦系数 -->
    <mu1 value="20.0"/>
    <!-- 法向摩擦系数 -->
    <mu2 value="20.0"/>
    <!-- 接触刚度系数 -->
    <kp value="1000000000.0"/>
    <!-- 阻尼系数 -->
    <kd value="1.0"/>
  </gazebo>
  <gazebo reference="right_wheel_link">
    <material>Gazebo/Blue</material>
  </gazebo>
  <link name="right_wheel_link">
    <visual>
      <origin rpy="1.57079 0 0" xyz="0 0 0"/>
      <geometry>
        <cylinder length="0.04" radius="0.032"/>
      </geometry>
      <material name="yellow">
        <color rgba="1.0 1.0 0.0 0.8"/>
      </material>
    </visual>
    <!-- 碰撞检测 -->
    <collision>
      <origin rpy="1.57079 0 0" xyz="0 0 0"/>
      <geometry>
        <cylinder length="0.04" radius="0.032"/>
      </geometry>
      <material name="yellow">
        <color rgba="1.0 1.0 0.0 0.8"/>
      </material>
    </collision>
    <inertial>
      <mass value="1.0"/>
      <inertia ixx="0.00038933333333333333" ixy="0.0" ixz="0.0" iyy="0.00038933333333333333" iyz="0.0" izz="0.000512"/>
    </inertial>
  </link>
  <joint name="right_wheel_joint" type="continuous">
    <parent link="base_link"/>
    <child link="right_wheel_link"/>
    <origin xyz="0 -0.1 -0.06"/>
    <axis xyz="0 1 0"/>
  </joint>
  <!-- 修改摩擦力系数 -->
  <gazebo reference="right_wheel_link">
    <!-- 切向摩擦系数 -->
    <mu1 value="20.0"/>
    <!-- 法向摩擦系数 -->
    <mu2 value="20.0"/>
    <!-- 接触刚度系数 -->
    <kp value="1000000000.0"/>
    <!-- 阻尼系数 -->
    <kd value="1.0"/>
  </gazebo>
  <gazebo reference="front_caster_link">
    <material>Gazebo/Blue</material>
  </gazebo>
  <link name="front_caster_link">
    <visual>
      <origin rpy="0 0 0" xyz="0 0 0"/>
      <geometry>
        <sphere radius="0.016"/>
      </geometry>
      <material name="yellow">
        <color rgba="1.0 1.0 0.0 0.8"/>
      </material>
    </visual>
    <!-- 碰撞检测 -->
    <collision>
      <origin rpy="0 0 0" xyz="0 0 0"/>
      <geometry>
        <sphere radius="0.016"/>
      </geometry>
      <material name="yellow">
        <color rgba="1.0 1.0 0.0 0.8"/>
      </material>
    </collision>
    <inertial>
      <mass value="1.0"/>
      <inertia ixx="0.0001024" ixy="0.0" ixz="0.0" iyy="0.0001024" iyz="0.0" izz="0.0001024"/>
    </inertial>
  </link>
  <joint name="front_caster_joint" type="fixed">
    <parent link="base_link"/>
    <child link="front_caster_link"/>
    <origin xyz="0.08 0.0 -0.076"/>
    <axis xyz="0 0 0"/>
  </joint>
  <!-- 修改摩擦力系数 -->
  <gazebo reference="front_caster_link">
    <!-- 切向摩擦系数 -->
    <mu1 value="0.0"/>
    <!-- 法向摩擦系数 -->
    <mu2 value="0.0"/>
    <!-- 接触刚度系数 -->
    <kp value="1000000000.0"/>
    <!-- 阻尼系数 -->
    <kd value="1.0"/>
  </gazebo>
  <gazebo reference="back_caster_link">
    <material>Gazebo/Blue</material>
  </gazebo>
  <link name="back_caster_link">
    <visual>
      <origin rpy="0 0 0" xyz="0 0 0"/>
      <geometry>
        <sphere radius="0.016"/>
      </geometry>
      <material name="yellow">
        <color rgba="1.0 1.0 0.0 0.8"/>
      </material>
    </visual>
    <!-- 碰撞检测 -->
    <collision>
      <origin rpy="0 0 0" xyz="0 0 0"/>
      <geometry>
        <sphere radius="0.016"/>
      </geometry>
      <material name="yellow">
        <color rgba="1.0 1.0 0.0 0.8"/>
      </material>
    </collision>
    <inertial>
      <mass value="1.0"/>
      <inertia ixx="0.0001024" ixy="0.0" ixz="0.0" iyy="0.0001024" iyz="0.0" izz="0.0001024"/>
    </inertial>
  </link>
  <joint name="back_caster_joint" type="fixed">
    <parent link="base_link"/>
    <child link="back_caster_link"/>
    <origin xyz="-0.08 0.0 -0.076"/>
    <axis xyz="0 0 0"/>
  </joint>
  <!-- 修改摩擦力系数 -->
  <gazebo reference="back_caster_link">
    <!-- 切向摩擦系数 -->
    <mu1 value="0.0"/>
    <!-- 法向摩擦系数 -->
    <mu2 value="0.0"/>
    <!-- 接触刚度系数 -->
    <kp value="1000000000.0"/>
    <!-- 阻尼系数 -->
    <kd value="1.0"/>
  </gazebo>
</robot>
