<?xml version="1.0" ?>
<!-- =================================================================================== -->
<!-- |    This document was autogenerated by xacro from src/fishbot_description/urdf/fishbot/fishbot.urdf.xacro | -->
<!-- |    EDITING THIS FILE BY HAND IS NOT RECOMMENDED                                 | -->
<!-- =================================================================================== -->
<robot name="fishbot">
  <!-- 底盘 -->
  <link name="base_footprint"/>
  <joint name="base_joint" type="fixed">
    <parent link="base_footprint"/>
    <child link="base_link"/>
    <origin rpy="0 0 0" xyz="0 0 0.091"/>
  </joint>
  <link name="base_link">
    <!-- 部件外观描述 -->
    <visual>
      <!-- 沿自己几何中心的偏移与旋转 -->
      <origin rpy="0 0 0" xyz="0 0 0"/>
      <!-- 几何形状 -->
      <geometry>
        <!-- 圆柱体， 半径为0.10m，高度为0.12m -->
        <cylinder length="0.12" radius="0.1"/>
      </geometry>
      <!-- 材料属性 -->
      <material name="white">
        <color rgba="1.0 1.0 1.0 0.5"/>
      </material>
    </visual>
    <!-- 碰撞属性 -->
    <collision>
      <origin rpy="0 0 0" xyz="0 0 0"/>
      <geometry>
        <cylinder length="0.12" radius="0.1"/>
      </geometry>
      <material name="white">
        <color rgba="1.0 1.0 1.0 0.5"/>
      </material>
    </collision>
    <inertial>
      <mass value="1.0"/>
      <inertia ixx="0.0037000000000000006" ixy="0.0" ixz="0.0" iyy="0.0037000000000000006" iyz="0.0" izz="0.005000000000000001"/>
    </inertial>
  </link>
  <link name="imu_link">
    <visual>
      <origin rpy="0 0 0" xyz="0 0 0"/>
      <geometry>
        <box size="0.02 0.02 0.02"/>
      </geometry>
      <material name="black">
        <color rgba="0 0 0 0.8"/>
      </material>
    </visual>
    <!-- 碰撞检测 -->
    <collision>
      <origin rpy="0 0 0" xyz="0 0 0"/>
      <geometry>
        <box size="0.02 0.02 0.02"/>
      </geometry>
      <material name="black">
        <color rgba="0 0 0 0.8"/>
      </material>
    </collision>
    <inertial>
      <mass value="1.0"/>
      <inertia ixx="6.666666666666667e-05" ixy="0.0" ixz="0.0" iyy="6.666666666666667e-05" iyz="0.0" izz="6.666666666666667e-05"/>
    </inertial>
  </link>
  <!-- 机器人IMU与身体的连接 -->
  <joint name="imu_joint" type="fixed">
    <parent link="base_link"/>
    <child link="imu_link"/>
    <!-- 子部件相对父部件的偏移与旋转 -->
    <origin xyz="0 0 0.02"/>
  </joint>
  <!-- 雷达支撑杆 -->
  <link name="laser_cylinder_link">
    <visual>
      <origin rpy="0 0 0" xyz="0 0 0"/>
      <geometry>
        <cylinder length="0.10" radius="0.01"/>
      </geometry>
      <material name="green">
        <color rgba="0.0 1.0 0.0 0.8"/>
      </material>
    </visual>
    <!-- 碰撞检测 -->
    <collision>
      <origin rpy="0 0 0" xyz="0 0 0"/>
      <geometry>
        <cylinder length="0.10" radius="0.01"/>
      </geometry>
      <material name="green">
        <color rgba="0.0 1.0 0.0 0.8"/>
      </material>
    </collision>
    <inertial>
      <mass value="1.0"/>
      <inertia ixx="0.0008583333333333335" ixy="0.0" ixz="0.0" iyy="0.0008583333333333335" iyz="0.0" izz="5e-05"/>
    </inertial>
  </link>
  <joint name="laser_cylinder_joint" type="fixed">
    <parent link="base_link"/>
    <child link="laser_cylinder_link"/>
    <origin xyz="0 0 0.1"/>
  </joint>
  <!-- 雷达 -->
  <link name="laser_link">
    <visual>
      <origin rpy="0 0 0" xyz="0 0 0"/>
      <geometry>
        <cylinder length="0.02" radius="0.02"/>
      </geometry>
      <material name="red">
        <color rgba="1.0 0.0 0.0 0.8"/>
      </material>
    </visual>
    <!-- 碰撞检测 -->
    <collision>
      <origin rpy="0 0 0" xyz="0 0 0"/>
      <geometry>
        <cylinder length="0.02" radius="0.02"/>
      </geometry>
      <material name="red">
        <color rgba="1.0 0.0 0.0 0.8"/>
      </material>
    </collision>
  </link>
  <joint name="laser_joint" type="fixed">
    <parent link="laser_cylinder_link"/>
    <child link="laser_link"/>
    <origin xyz="0 0 0.05"/>
  </joint>
  <link name="camera_link">
    <visual>
      <origin rpy="0 0 0" xyz="0 0 0.0"/>
      <geometry>
        <box size="0.02 0.10 0.02"/>
      </geometry>
      <material name="green">
        <color rgba="0.0 1.0 0.0 0.8"/>
      </material>
    </visual>
    <!-- 碰撞检测 -->
    <collision>
      <origin rpy="0 0 0" xyz="0 0 0.0"/>
      <geometry>
        <box size="0.02 0.10 0.02"/>
      </geometry>
      <material name="green">
        <color rgba="0.0 1.0 0.0 0.8"/>
      </material>
    </collision>
    <inertial>
      <mass value="1.0"/>
      <inertia ixx="6.666666666666667e-05" ixy="0.0" ixz="0.0" iyy="0.0008666666666666667" iyz="0.0" izz="0.0008666666666666667"/>
    </inertial>
  </link>
  <!-- 机器人相机与身体的连接 -->
  <joint name="camera_joint" type="fixed">
    <parent link="base_link"/>
    <child link="camera_link"/>
    <!-- 子部件相对父部件的偏移与旋转 -->
    <origin xyz="0.1 0 0.075"/>
  </joint>
  <link name="left_wheel_link">
    <visual>
      <origin rpy="1.57079 0 0" xyz="0 0 0"/>
      <geometry>
        <cylinder length="0.04" radius="0.032"/>
      </geometry>
      <material name="yellow">
        <color rgba="1.0 1.0 0.0 0.8"/>
      </material>
    </visual>
    <!-- 碰撞检测 -->
    <collision>
      <origin rpy="1.57079 0 0" xyz="0 0 0"/>
      <geometry>
        <cylinder length="0.04" radius="0.032"/>
      </geometry>
      <material name="yellow">
        <color rgba="1.0 1.0 0.0 0.8"/>
      </material>
    </collision>
    <inertial>
      <mass value="1.0"/>
      <inertia ixx="0.00038933333333333333" ixy="0.0" ixz="0.0" iyy="0.00038933333333333333" iyz="0.0" izz="0.000512"/>
    </inertial>
  </link>
  <joint name="left_wheel_joint" type="continuous">
    <parent link="base_link"/>
    <child link="left_wheel_link"/>
    <origin xyz="0 0.1 -0.06"/>
    <axis xyz="0 1 0"/>
  </joint>
  <link name="right_wheel_link">
    <visual>
      <origin rpy="1.57079 0 0" xyz="0 0 0"/>
      <geometry>
        <cylinder length="0.04" radius="0.032"/>
      </geometry>
      <material name="yellow">
        <color rgba="1.0 1.0 0.0 0.8"/>
      </material>
    </visual>
    <!-- 碰撞检测 -->
    <collision>
      <origin rpy="1.57079 0 0" xyz="0 0 0"/>
      <geometry>
        <cylinder length="0.04" radius="0.032"/>
      </geometry>
      <material name="yellow">
        <color rgba="1.0 1.0 0.0 0.8"/>
      </material>
    </collision>
    <inertial>
      <mass value="1.0"/>
      <inertia ixx="0.00038933333333333333" ixy="0.0" ixz="0.0" iyy="0.00038933333333333333" iyz="0.0" izz="0.000512"/>
    </inertial>
  </link>
  <joint name="right_wheel_joint" type="continuous">
    <parent link="base_link"/>
    <child link="right_wheel_link"/>
    <origin xyz="0 -0.1 -0.06"/>
    <axis xyz="0 1 0"/>
  </joint>
  <link name="front_caster_link">
    <visual>
      <origin rpy="0 0 0" xyz="0 0 0"/>
      <geometry>
        <sphere radius="0.016"/>
      </geometry>
      <material name="yellow">
        <color rgba="1.0 1.0 0.0 0.8"/>
      </material>
    </visual>
    <!-- 碰撞检测 -->
    <collision>
      <origin rpy="0 0 0" xyz="0 0 0"/>
      <geometry>
        <sphere radius="0.016"/>
      </geometry>
      <material name="yellow">
        <color rgba="1.0 1.0 0.0 0.8"/>
      </material>
    </collision>
    <inertial>
      <mass value="1.0"/>
      <inertia ixx="0.0001024" ixy="0.0" ixz="0.0" iyy="0.0001024" iyz="0.0" izz="0.0001024"/>
    </inertial>
  </link>
  <joint name="front_caster_joint" type="fixed">
    <parent link="base_link"/>
    <child link="front_caster_link"/>
    <origin xyz="0.08 0.0 -0.076"/>
    <axis xyz="0 0 0"/>
  </joint>
  <link name="back_caster_link">
    <visual>
      <origin rpy="0 0 0" xyz="0 0 0"/>
      <geometry>
        <sphere radius="0.016"/>
      </geometry>
      <material name="yellow">
        <color rgba="1.0 1.0 0.0 0.8"/>
      </material>
    </visual>
    <!-- 碰撞检测 -->
    <collision>
      <origin rpy="0 0 0" xyz="0 0 0"/>
      <geometry>
        <sphere radius="0.016"/>
      </geometry>
      <material name="yellow">
        <color rgba="1.0 1.0 0.0 0.8"/>
      </material>
    </collision>
    <inertial>
      <mass value="1.0"/>
      <inertia ixx="0.0001024" ixy="0.0" ixz="0.0" iyy="0.0001024" iyz="0.0" izz="0.0001024"/>
    </inertial>
  </link>
  <joint name="back_caster_joint" type="fixed">
    <parent link="base_link"/>
    <child link="back_caster_link"/>
    <origin xyz="-0.08 0.0 -0.076"/>
    <axis xyz="0 0 0"/>
  </joint>
</robot>
