<mujoco model="cr3_robot">
  <compiler angle="radian"/>

  <asset>
    <mesh name="base_link" file="../mesh/base_link.STL"/>
    <mesh name="Link1" file="../mesh/Link1.STL"/>
    <mesh name="Link2" file="../mesh/Link2.STL"/>
    <mesh name="Link3" file="../mesh/Link3.STL"/>
    <mesh name="Link4" file="../mesh/Link4.STL"/>
    <mesh name="Link5" file="../mesh/Link5.STL"/>
    <mesh name="Link6" file="../mesh/Link6.STL"/>
  </asset>

  <worldbody>
    <geom type="mesh" rgba="1 1 1 1" mesh="base_link"/>
    <body name="Link1" pos="0 0 0.1283">
      <inertial pos="-3.68658e-05 -0.00394517 0.00364038" quat="0.668079 0.224285 -0.228154 0.671798" mass="1.31101" diaginertia="0.00217669 0.00202531 0.00164384"/>
      <joint name="joint1" pos="0 0 0" axis="0 0 1" range="-6.27 6.27"/>
      <geom type="mesh" rgba="1 1 1 1" mesh="Link1"/>
      <body name="Link2" quat="0.499998 0.5 0.5 -0.500002">
        <inertial pos="-0.129235 1.44054e-05 0.133174" quat="0.483434 0.51644 0.516337 0.482677" mass="3.40044" diaginertia="0.0063233 0.00578813 0.00450009"/>
        <joint name="joint2" pos="0 0 0" axis="0 0 1" range="-6.27 6.27"/>
        <geom type="mesh" rgba="1 1 1 1" mesh="Link2"/>
        <body name="Link3" pos="-0.274 0 0">
          <inertial pos="-0.119823 8.63344e-08 0.00998766" quat="0.432122 0.559713 0.559721 0.432092" mass="2.21449" diaginertia="0.00313635 0.0028872 0.00232519"/>
          <joint name="joint3" pos="0 0 0" axis="0 0 1" range="-2.86 2.86"/>
          <geom type="mesh" rgba="1 1 1 1" mesh="Link3"/>
          <body name="Link4" pos="-0.23 0 0.1283" quat="0.707105 0 0 -0.707108">
            <inertial pos="1.7468e-07 0.00345224 -0.0028731" quat="0.601412 0.371834 -0.371869 0.601462" mass="0.842273" diaginertia="0.00106054 0.0010039 0.000726821"/>
            <joint name="joint4" pos="0 0 0" axis="0 0 1" range="-6.27 6.27"/>
            <geom type="mesh" rgba="1 1 1 1" mesh="Link4"/>
            <body name="Link5" pos="0 -0.116 0" quat="0.707105 0.707108 0 0">
              <inertial pos="-1.74604e-07 -0.00333192 -0.00286781" quat="0.37287 0.600892 -0.600772 0.372788" mass="0.843693" diaginertia="0.00106485 0.00100855 0.000728263"/>
              <joint name="joint5" pos="0 0 0" axis="0 0 1" range="-6.27 6.27"/>
              <geom type="mesh" rgba="1 1 1 1" mesh="Link5"/>
              <body name="Link6" pos="0 0.105 0" quat="0.707105 -0.707108 0 0">
                <inertial pos="-5.77233e-07 0.000270131 -0.0201387" quat="-0.00177703 0.707105 -0.000182648 0.707107" mass="0.159409" diaginertia="0.000131911 8.35925e-05 8.29484e-05"/>
                <joint name="joint6" pos="0 0 0" axis="0 0 1" range="-6.27 6.27"/>
                <geom type="mesh" rgba="1 1 1 1" mesh="Link6"/>
              </body>
            </body>
          </body>
        </body>
      </body>
    </body>
  </worldbody>
</mujoco>
